ERROR 2025-03-27 13:10:39,602 exception 36116 6200799232 Invalid HTTP_HOST header: '127.0.0.1:8000'. You may need to add '127.0.0.1' to ALLOWED_HOSTS.
Traceback (most recent call last):
  File "/Users/petergangmei/Developer/Projects/django/quiz /venv/lib/python3.13/site-packages/django/core/handlers/exception.py", line 55, in inner
    response = get_response(request)
  File "/Users/petergangmei/Developer/Projects/django/quiz /venv/lib/python3.13/site-packages/django/utils/deprecation.py", line 128, in __call__
    response = self.process_request(request)
  File "/Users/petergangmei/Developer/Projects/django/quiz /venv/lib/python3.13/site-packages/django/middleware/common.py", line 48, in process_request
    host = request.get_host()
  File "/Users/petergangmei/Developer/Projects/django/quiz /venv/lib/python3.13/site-packages/django/http/request.py", line 151, in get_host
    raise DisallowedHost(msg)
django.core.exceptions.DisallowedHost: Invalid HTTP_HOST header: '127.0.0.1:8000'. You may need to add '127.0.0.1' to ALLOWED_HOSTS.
ERROR 2025-03-27 13:10:55,966 exception 36116 6200799232 Invalid HTTP_HOST header: '127.0.0.1:8000'. You may need to add '127.0.0.1' to ALLOWED_HOSTS.
Traceback (most recent call last):
  File "/Users/petergangmei/Developer/Projects/django/quiz /venv/lib/python3.13/site-packages/django/core/handlers/exception.py", line 55, in inner
    response = get_response(request)
  File "/Users/petergangmei/Developer/Projects/django/quiz /venv/lib/python3.13/site-packages/django/utils/deprecation.py", line 128, in __call__
    response = self.process_request(request)
  File "/Users/petergangmei/Developer/Projects/django/quiz /venv/lib/python3.13/site-packages/django/middleware/common.py", line 48, in process_request
    host = request.get_host()
  File "/Users/petergangmei/Developer/Projects/django/quiz /venv/lib/python3.13/site-packages/django/http/request.py", line 151, in get_host
    raise DisallowedHost(msg)
django.core.exceptions.DisallowedHost: Invalid HTTP_HOST header: '127.0.0.1:8000'. You may need to add '127.0.0.1' to ALLOWED_HOSTS.
ERROR 2025-03-27 13:10:56,025 exception 36116 6217625600 Invalid HTTP_HOST header: '127.0.0.1:8000'. You may need to add '127.0.0.1' to ALLOWED_HOSTS.
Traceback (most recent call last):
  File "/Users/petergangmei/Developer/Projects/django/quiz /venv/lib/python3.13/site-packages/django/core/handlers/exception.py", line 55, in inner
    response = get_response(request)
  File "/Users/petergangmei/Developer/Projects/django/quiz /venv/lib/python3.13/site-packages/django/utils/deprecation.py", line 128, in __call__
    response = self.process_request(request)
  File "/Users/petergangmei/Developer/Projects/django/quiz /venv/lib/python3.13/site-packages/django/middleware/common.py", line 48, in process_request
    host = request.get_host()
  File "/Users/petergangmei/Developer/Projects/django/quiz /venv/lib/python3.13/site-packages/django/http/request.py", line 151, in get_host
    raise DisallowedHost(msg)
django.core.exceptions.DisallowedHost: Invalid HTTP_HOST header: '127.0.0.1:8000'. You may need to add '127.0.0.1' to ALLOWED_HOSTS.
ERROR 2025-03-27 13:10:56,601 exception 36116 6234451968 Invalid HTTP_HOST header: '127.0.0.1:8000'. You may need to add '127.0.0.1' to ALLOWED_HOSTS.
Traceback (most recent call last):
  File "/Users/petergangmei/Developer/Projects/django/quiz /venv/lib/python3.13/site-packages/django/core/handlers/exception.py", line 55, in inner
    response = get_response(request)
  File "/Users/petergangmei/Developer/Projects/django/quiz /venv/lib/python3.13/site-packages/django/utils/deprecation.py", line 128, in __call__
    response = self.process_request(request)
  File "/Users/petergangmei/Developer/Projects/django/quiz /venv/lib/python3.13/site-packages/django/middleware/common.py", line 48, in process_request
    host = request.get_host()
  File "/Users/petergangmei/Developer/Projects/django/quiz /venv/lib/python3.13/site-packages/django/http/request.py", line 151, in get_host
    raise DisallowedHost(msg)
django.core.exceptions.DisallowedHost: Invalid HTTP_HOST header: '127.0.0.1:8000'. You may need to add '127.0.0.1' to ALLOWED_HOSTS.
ERROR 2025-03-27 13:10:56,668 exception 36116 6251278336 Invalid HTTP_HOST header: '127.0.0.1:8000'. You may need to add '127.0.0.1' to ALLOWED_HOSTS.
Traceback (most recent call last):
  File "/Users/petergangmei/Developer/Projects/django/quiz /venv/lib/python3.13/site-packages/django/core/handlers/exception.py", line 55, in inner
    response = get_response(request)
  File "/Users/petergangmei/Developer/Projects/django/quiz /venv/lib/python3.13/site-packages/django/utils/deprecation.py", line 128, in __call__
    response = self.process_request(request)
  File "/Users/petergangmei/Developer/Projects/django/quiz /venv/lib/python3.13/site-packages/django/middleware/common.py", line 48, in process_request
    host = request.get_host()
  File "/Users/petergangmei/Developer/Projects/django/quiz /venv/lib/python3.13/site-packages/django/http/request.py", line 151, in get_host
    raise DisallowedHost(msg)
django.core.exceptions.DisallowedHost: Invalid HTTP_HOST header: '127.0.0.1:8000'. You may need to add '127.0.0.1' to ALLOWED_HOSTS.
ERROR 2025-03-27 13:11:08,373 exception 36153 6199209984 Invalid HTTP_HOST header: '127.0.0.1:8000'. You may need to add '127.0.0.1' to ALLOWED_HOSTS.
Traceback (most recent call last):
  File "/Users/petergangmei/Developer/Projects/django/quiz /venv/lib/python3.13/site-packages/django/core/handlers/exception.py", line 55, in inner
    response = get_response(request)
  File "/Users/petergangmei/Developer/Projects/django/quiz /venv/lib/python3.13/site-packages/django/utils/deprecation.py", line 128, in __call__
    response = self.process_request(request)
  File "/Users/petergangmei/Developer/Projects/django/quiz /venv/lib/python3.13/site-packages/django/middleware/common.py", line 48, in process_request
    host = request.get_host()
  File "/Users/petergangmei/Developer/Projects/django/quiz /venv/lib/python3.13/site-packages/django/http/request.py", line 151, in get_host
    raise DisallowedHost(msg)
django.core.exceptions.DisallowedHost: Invalid HTTP_HOST header: '127.0.0.1:8000'. You may need to add '127.0.0.1' to ALLOWED_HOSTS.
ERROR 2025-03-27 13:11:08,534 exception 36153 6216036352 Invalid HTTP_HOST header: '127.0.0.1:8000'. You may need to add '127.0.0.1' to ALLOWED_HOSTS.
Traceback (most recent call last):
  File "/Users/petergangmei/Developer/Projects/django/quiz /venv/lib/python3.13/site-packages/django/core/handlers/exception.py", line 55, in inner
    response = get_response(request)
  File "/Users/petergangmei/Developer/Projects/django/quiz /venv/lib/python3.13/site-packages/django/utils/deprecation.py", line 128, in __call__
    response = self.process_request(request)
  File "/Users/petergangmei/Developer/Projects/django/quiz /venv/lib/python3.13/site-packages/django/middleware/common.py", line 48, in process_request
    host = request.get_host()
  File "/Users/petergangmei/Developer/Projects/django/quiz /venv/lib/python3.13/site-packages/django/http/request.py", line 151, in get_host
    raise DisallowedHost(msg)
django.core.exceptions.DisallowedHost: Invalid HTTP_HOST header: '127.0.0.1:8000'. You may need to add '127.0.0.1' to ALLOWED_HOSTS.
ERROR 2025-03-27 13:11:25,570 exception 36153 6199209984 Invalid HTTP_HOST header: '127.0.0.1:8000'. You may need to add '127.0.0.1' to ALLOWED_HOSTS.
Traceback (most recent call last):
  File "/Users/petergangmei/Developer/Projects/django/quiz /venv/lib/python3.13/site-packages/django/core/handlers/exception.py", line 55, in inner
    response = get_response(request)
  File "/Users/petergangmei/Developer/Projects/django/quiz /venv/lib/python3.13/site-packages/django/utils/deprecation.py", line 128, in __call__
    response = self.process_request(request)
  File "/Users/petergangmei/Developer/Projects/django/quiz /venv/lib/python3.13/site-packages/django/middleware/common.py", line 48, in process_request
    host = request.get_host()
  File "/Users/petergangmei/Developer/Projects/django/quiz /venv/lib/python3.13/site-packages/django/http/request.py", line 151, in get_host
    raise DisallowedHost(msg)
django.core.exceptions.DisallowedHost: Invalid HTTP_HOST header: '127.0.0.1:8000'. You may need to add '127.0.0.1' to ALLOWED_HOSTS.
ERROR 2025-03-27 13:11:25,708 exception 36153 6216036352 Invalid HTTP_HOST header: '127.0.0.1:8000'. You may need to add '127.0.0.1' to ALLOWED_HOSTS.
Traceback (most recent call last):
  File "/Users/petergangmei/Developer/Projects/django/quiz /venv/lib/python3.13/site-packages/django/core/handlers/exception.py", line 55, in inner
    response = get_response(request)
  File "/Users/petergangmei/Developer/Projects/django/quiz /venv/lib/python3.13/site-packages/django/utils/deprecation.py", line 128, in __call__
    response = self.process_request(request)
  File "/Users/petergangmei/Developer/Projects/django/quiz /venv/lib/python3.13/site-packages/django/middleware/common.py", line 48, in process_request
    host = request.get_host()
  File "/Users/petergangmei/Developer/Projects/django/quiz /venv/lib/python3.13/site-packages/django/http/request.py", line 151, in get_host
    raise DisallowedHost(msg)
django.core.exceptions.DisallowedHost: Invalid HTTP_HOST header: '127.0.0.1:8000'. You may need to add '127.0.0.1' to ALLOWED_HOSTS.
ERROR 2025-03-27 13:11:26,301 exception 36153 6199209984 Invalid HTTP_HOST header: '127.0.0.1:8000'. You may need to add '127.0.0.1' to ALLOWED_HOSTS.
Traceback (most recent call last):
  File "/Users/petergangmei/Developer/Projects/django/quiz /venv/lib/python3.13/site-packages/django/core/handlers/exception.py", line 55, in inner
    response = get_response(request)
  File "/Users/petergangmei/Developer/Projects/django/quiz /venv/lib/python3.13/site-packages/django/utils/deprecation.py", line 128, in __call__
    response = self.process_request(request)
  File "/Users/petergangmei/Developer/Projects/django/quiz /venv/lib/python3.13/site-packages/django/middleware/common.py", line 48, in process_request
    host = request.get_host()
  File "/Users/petergangmei/Developer/Projects/django/quiz /venv/lib/python3.13/site-packages/django/http/request.py", line 151, in get_host
    raise DisallowedHost(msg)
django.core.exceptions.DisallowedHost: Invalid HTTP_HOST header: '127.0.0.1:8000'. You may need to add '127.0.0.1' to ALLOWED_HOSTS.
ERROR 2025-03-27 13:11:26,390 exception 36153 6232862720 Invalid HTTP_HOST header: '127.0.0.1:8000'. You may need to add '127.0.0.1' to ALLOWED_HOSTS.
Traceback (most recent call last):
  File "/Users/petergangmei/Developer/Projects/django/quiz /venv/lib/python3.13/site-packages/django/core/handlers/exception.py", line 55, in inner
    response = get_response(request)
  File "/Users/petergangmei/Developer/Projects/django/quiz /venv/lib/python3.13/site-packages/django/utils/deprecation.py", line 128, in __call__
    response = self.process_request(request)
  File "/Users/petergangmei/Developer/Projects/django/quiz /venv/lib/python3.13/site-packages/django/middleware/common.py", line 48, in process_request
    host = request.get_host()
  File "/Users/petergangmei/Developer/Projects/django/quiz /venv/lib/python3.13/site-packages/django/http/request.py", line 151, in get_host
    raise DisallowedHost(msg)
django.core.exceptions.DisallowedHost: Invalid HTTP_HOST header: '127.0.0.1:8000'. You may need to add '127.0.0.1' to ALLOWED_HOSTS.
ERROR 2025-03-27 13:11:27,251 exception 36153 6199209984 Invalid HTTP_HOST header: '127.0.0.1:8000'. You may need to add '127.0.0.1' to ALLOWED_HOSTS.
Traceback (most recent call last):
  File "/Users/petergangmei/Developer/Projects/django/quiz /venv/lib/python3.13/site-packages/django/core/handlers/exception.py", line 55, in inner
    response = get_response(request)
  File "/Users/petergangmei/Developer/Projects/django/quiz /venv/lib/python3.13/site-packages/django/utils/deprecation.py", line 128, in __call__
    response = self.process_request(request)
  File "/Users/petergangmei/Developer/Projects/django/quiz /venv/lib/python3.13/site-packages/django/middleware/common.py", line 48, in process_request
    host = request.get_host()
  File "/Users/petergangmei/Developer/Projects/django/quiz /venv/lib/python3.13/site-packages/django/http/request.py", line 151, in get_host
    raise DisallowedHost(msg)
django.core.exceptions.DisallowedHost: Invalid HTTP_HOST header: '127.0.0.1:8000'. You may need to add '127.0.0.1' to ALLOWED_HOSTS.
ERROR 2025-03-27 13:11:27,347 exception 36153 6216036352 Invalid HTTP_HOST header: '127.0.0.1:8000'. You may need to add '127.0.0.1' to ALLOWED_HOSTS.
Traceback (most recent call last):
  File "/Users/petergangmei/Developer/Projects/django/quiz /venv/lib/python3.13/site-packages/django/core/handlers/exception.py", line 55, in inner
    response = get_response(request)
  File "/Users/petergangmei/Developer/Projects/django/quiz /venv/lib/python3.13/site-packages/django/utils/deprecation.py", line 128, in __call__
    response = self.process_request(request)
  File "/Users/petergangmei/Developer/Projects/django/quiz /venv/lib/python3.13/site-packages/django/middleware/common.py", line 48, in process_request
    host = request.get_host()
  File "/Users/petergangmei/Developer/Projects/django/quiz /venv/lib/python3.13/site-packages/django/http/request.py", line 151, in get_host
    raise DisallowedHost(msg)
django.core.exceptions.DisallowedHost: Invalid HTTP_HOST header: '127.0.0.1:8000'. You may need to add '127.0.0.1' to ALLOWED_HOSTS.
ERROR 2025-03-27 13:11:41,911 exception 36153 6199209984 Invalid HTTP_HOST header: '127.0.0.1:8000'. You may need to add '127.0.0.1' to ALLOWED_HOSTS.
Traceback (most recent call last):
  File "/Users/petergangmei/Developer/Projects/django/quiz /venv/lib/python3.13/site-packages/django/core/handlers/exception.py", line 55, in inner
    response = get_response(request)
  File "/Users/petergangmei/Developer/Projects/django/quiz /venv/lib/python3.13/site-packages/django/utils/deprecation.py", line 128, in __call__
    response = self.process_request(request)
  File "/Users/petergangmei/Developer/Projects/django/quiz /venv/lib/python3.13/site-packages/django/middleware/common.py", line 48, in process_request
    host = request.get_host()
  File "/Users/petergangmei/Developer/Projects/django/quiz /venv/lib/python3.13/site-packages/django/http/request.py", line 151, in get_host
    raise DisallowedHost(msg)
django.core.exceptions.DisallowedHost: Invalid HTTP_HOST header: '127.0.0.1:8000'. You may need to add '127.0.0.1' to ALLOWED_HOSTS.
ERROR 2025-03-27 13:11:42,017 exception 36153 6232862720 Invalid HTTP_HOST header: '127.0.0.1:8000'. You may need to add '127.0.0.1' to ALLOWED_HOSTS.
Traceback (most recent call last):
  File "/Users/petergangmei/Developer/Projects/django/quiz /venv/lib/python3.13/site-packages/django/core/handlers/exception.py", line 55, in inner
    response = get_response(request)
  File "/Users/petergangmei/Developer/Projects/django/quiz /venv/lib/python3.13/site-packages/django/utils/deprecation.py", line 128, in __call__
    response = self.process_request(request)
  File "/Users/petergangmei/Developer/Projects/django/quiz /venv/lib/python3.13/site-packages/django/middleware/common.py", line 48, in process_request
    host = request.get_host()
  File "/Users/petergangmei/Developer/Projects/django/quiz /venv/lib/python3.13/site-packages/django/http/request.py", line 151, in get_host
    raise DisallowedHost(msg)
django.core.exceptions.DisallowedHost: Invalid HTTP_HOST header: '127.0.0.1:8000'. You may need to add '127.0.0.1' to ALLOWED_HOSTS.
ERROR 2025-03-27 13:11:42,551 exception 36153 6199209984 Invalid HTTP_HOST header: '127.0.0.1:8000'. You may need to add '127.0.0.1' to ALLOWED_HOSTS.
Traceback (most recent call last):
  File "/Users/petergangmei/Developer/Projects/django/quiz /venv/lib/python3.13/site-packages/django/core/handlers/exception.py", line 55, in inner
    response = get_response(request)
  File "/Users/petergangmei/Developer/Projects/django/quiz /venv/lib/python3.13/site-packages/django/utils/deprecation.py", line 128, in __call__
    response = self.process_request(request)
  File "/Users/petergangmei/Developer/Projects/django/quiz /venv/lib/python3.13/site-packages/django/middleware/common.py", line 48, in process_request
    host = request.get_host()
  File "/Users/petergangmei/Developer/Projects/django/quiz /venv/lib/python3.13/site-packages/django/http/request.py", line 151, in get_host
    raise DisallowedHost(msg)
django.core.exceptions.DisallowedHost: Invalid HTTP_HOST header: '127.0.0.1:8000'. You may need to add '127.0.0.1' to ALLOWED_HOSTS.
ERROR 2025-03-27 13:11:42,642 exception 36153 6216036352 Invalid HTTP_HOST header: '127.0.0.1:8000'. You may need to add '127.0.0.1' to ALLOWED_HOSTS.
Traceback (most recent call last):
  File "/Users/petergangmei/Developer/Projects/django/quiz /venv/lib/python3.13/site-packages/django/core/handlers/exception.py", line 55, in inner
    response = get_response(request)
  File "/Users/petergangmei/Developer/Projects/django/quiz /venv/lib/python3.13/site-packages/django/utils/deprecation.py", line 128, in __call__
    response = self.process_request(request)
  File "/Users/petergangmei/Developer/Projects/django/quiz /venv/lib/python3.13/site-packages/django/middleware/common.py", line 48, in process_request
    host = request.get_host()
  File "/Users/petergangmei/Developer/Projects/django/quiz /venv/lib/python3.13/site-packages/django/http/request.py", line 151, in get_host
    raise DisallowedHost(msg)
django.core.exceptions.DisallowedHost: Invalid HTTP_HOST header: '127.0.0.1:8000'. You may need to add '127.0.0.1' to ALLOWED_HOSTS.
ERROR 2025-03-27 13:12:19,962 exception 36153 6199209984 Invalid HTTP_HOST header: '127.0.0.1:8000'. You may need to add '127.0.0.1' to ALLOWED_HOSTS.
Traceback (most recent call last):
  File "/Users/petergangmei/Developer/Projects/django/quiz /venv/lib/python3.13/site-packages/django/core/handlers/exception.py", line 55, in inner
    response = get_response(request)
  File "/Users/petergangmei/Developer/Projects/django/quiz /venv/lib/python3.13/site-packages/django/utils/deprecation.py", line 128, in __call__
    response = self.process_request(request)
  File "/Users/petergangmei/Developer/Projects/django/quiz /venv/lib/python3.13/site-packages/django/middleware/common.py", line 48, in process_request
    host = request.get_host()
  File "/Users/petergangmei/Developer/Projects/django/quiz /venv/lib/python3.13/site-packages/django/http/request.py", line 151, in get_host
    raise DisallowedHost(msg)
django.core.exceptions.DisallowedHost: Invalid HTTP_HOST header: '127.0.0.1:8000'. You may need to add '127.0.0.1' to ALLOWED_HOSTS.
ERROR 2025-03-27 13:12:20,083 exception 36153 6232862720 Invalid HTTP_HOST header: '127.0.0.1:8000'. You may need to add '127.0.0.1' to ALLOWED_HOSTS.
Traceback (most recent call last):
  File "/Users/petergangmei/Developer/Projects/django/quiz /venv/lib/python3.13/site-packages/django/core/handlers/exception.py", line 55, in inner
    response = get_response(request)
  File "/Users/petergangmei/Developer/Projects/django/quiz /venv/lib/python3.13/site-packages/django/utils/deprecation.py", line 128, in __call__
    response = self.process_request(request)
  File "/Users/petergangmei/Developer/Projects/django/quiz /venv/lib/python3.13/site-packages/django/middleware/common.py", line 48, in process_request
    host = request.get_host()
  File "/Users/petergangmei/Developer/Projects/django/quiz /venv/lib/python3.13/site-packages/django/http/request.py", line 151, in get_host
    raise DisallowedHost(msg)
django.core.exceptions.DisallowedHost: Invalid HTTP_HOST header: '127.0.0.1:8000'. You may need to add '127.0.0.1' to ALLOWED_HOSTS.
ERROR 2025-03-28 07:28:26,068 log 25044 6130544640 Internal Server Error: /
Traceback (most recent call last):
  File "/Users/petergangmei/Developer/Projects/django/quiz /venv/lib/python3.13/site-packages/django/urls/base.py", line 71, in reverse
    extra, resolver = resolver.namespace_dict[ns]
                      ~~~~~~~~~~~~~~~~~~~~~~~^^^^
KeyError: 'app'

During handling of the above exception, another exception occurred:

Traceback (most recent call last):
  File "/Users/petergangmei/Developer/Projects/django/quiz /venv/lib/python3.13/site-packages/django/core/handlers/exception.py", line 55, in inner
    response = get_response(request)
  File "/Users/petergangmei/Developer/Projects/django/quiz /venv/lib/python3.13/site-packages/django/core/handlers/base.py", line 197, in _get_response
    response = wrapped_callback(request, *callback_args, **callback_kwargs)
  File "/Users/petergangmei/Developer/Projects/django/quiz /app/views.py", line 15, in home
    return render(request, 'home.html', {'quizzes': quizzes})
  File "/Users/petergangmei/Developer/Projects/django/quiz /venv/lib/python3.13/site-packages/django/shortcuts.py", line 25, in render
    content = loader.render_to_string(template_name, context, request, using=using)
  File "/Users/petergangmei/Developer/Projects/django/quiz /venv/lib/python3.13/site-packages/django/template/loader.py", line 62, in render_to_string
    return template.render(context, request)
           ~~~~~~~~~~~~~~~^^^^^^^^^^^^^^^^^^
  File "/Users/petergangmei/Developer/Projects/django/quiz /venv/lib/python3.13/site-packages/django/template/backends/django.py", line 107, in render
    return self.template.render(context)
           ~~~~~~~~~~~~~~~~~~~~^^^^^^^^^
  File "/Users/petergangmei/Developer/Projects/django/quiz /venv/lib/python3.13/site-packages/django/template/base.py", line 171, in render
    return self._render(context)
           ~~~~~~~~~~~~^^^^^^^^^
  File "/Users/petergangmei/Developer/Projects/django/quiz /venv/lib/python3.13/site-packages/django/template/base.py", line 163, in _render
    return self.nodelist.render(context)
           ~~~~~~~~~~~~~~~~~~~~^^^^^^^^^
  File "/Users/petergangmei/Developer/Projects/django/quiz /venv/lib/python3.13/site-packages/django/template/base.py", line 1008, in render
    return SafeString("".join([node.render_annotated(context) for node in self]))
                               ~~~~~~~~~~~~~~~~~~~~~^^^^^^^^^
  File "/Users/petergangmei/Developer/Projects/django/quiz /venv/lib/python3.13/site-packages/django/template/base.py", line 969, in render_annotated
    return self.render(context)
           ~~~~~~~~~~~^^^^^^^^^
  File "/Users/petergangmei/Developer/Projects/django/quiz /venv/lib/python3.13/site-packages/django/template/loader_tags.py", line 159, in render
    return compiled_parent._render(context)
           ~~~~~~~~~~~~~~~~~~~~~~~^^^^^^^^^
  File "/Users/petergangmei/Developer/Projects/django/quiz /venv/lib/python3.13/site-packages/django/template/base.py", line 163, in _render
    return self.nodelist.render(context)
           ~~~~~~~~~~~~~~~~~~~~^^^^^^^^^
  File "/Users/petergangmei/Developer/Projects/django/quiz /venv/lib/python3.13/site-packages/django/template/base.py", line 1008, in render
    return SafeString("".join([node.render_annotated(context) for node in self]))
                               ~~~~~~~~~~~~~~~~~~~~~^^^^^^^^^
  File "/Users/petergangmei/Developer/Projects/django/quiz /venv/lib/python3.13/site-packages/django/template/base.py", line 969, in render_annotated
    return self.render(context)
           ~~~~~~~~~~~^^^^^^^^^
  File "/Users/petergangmei/Developer/Projects/django/quiz /venv/lib/python3.13/site-packages/django/template/loader_tags.py", line 210, in render
    return template.render(context)
           ~~~~~~~~~~~~~~~^^^^^^^^^
  File "/Users/petergangmei/Developer/Projects/django/quiz /venv/lib/python3.13/site-packages/django/template/base.py", line 173, in render
    return self._render(context)
           ~~~~~~~~~~~~^^^^^^^^^
  File "/Users/petergangmei/Developer/Projects/django/quiz /venv/lib/python3.13/site-packages/django/template/base.py", line 163, in _render
    return self.nodelist.render(context)
           ~~~~~~~~~~~~~~~~~~~~^^^^^^^^^
  File "/Users/petergangmei/Developer/Projects/django/quiz /venv/lib/python3.13/site-packages/django/template/base.py", line 1008, in render
    return SafeString("".join([node.render_annotated(context) for node in self]))
                               ~~~~~~~~~~~~~~~~~~~~~^^^^^^^^^
  File "/Users/petergangmei/Developer/Projects/django/quiz /venv/lib/python3.13/site-packages/django/template/base.py", line 969, in render_annotated
    return self.render(context)
           ~~~~~~~~~~~^^^^^^^^^
  File "/Users/petergangmei/Developer/Projects/django/quiz /venv/lib/python3.13/site-packages/django/template/defaulttags.py", line 480, in render
    url = reverse(view_name, args=args, kwargs=kwargs, current_app=current_app)
  File "/Users/petergangmei/Developer/Projects/django/quiz /venv/lib/python3.13/site-packages/django/urls/base.py", line 82, in reverse
    raise NoReverseMatch("%s is not a registered namespace" % key)
django.urls.exceptions.NoReverseMatch: 'app' is not a registered namespace
ERROR 2025-03-28 07:28:26,071 log 25044 6147371008 Internal Server Error: /
Traceback (most recent call last):
  File "/Users/petergangmei/Developer/Projects/django/quiz /venv/lib/python3.13/site-packages/django/urls/base.py", line 71, in reverse
    extra, resolver = resolver.namespace_dict[ns]
                      ~~~~~~~~~~~~~~~~~~~~~~~^^^^
KeyError: 'app'

During handling of the above exception, another exception occurred:

Traceback (most recent call last):
  File "/Users/petergangmei/Developer/Projects/django/quiz /venv/lib/python3.13/site-packages/django/core/handlers/exception.py", line 55, in inner
    response = get_response(request)
  File "/Users/petergangmei/Developer/Projects/django/quiz /venv/lib/python3.13/site-packages/django/core/handlers/base.py", line 197, in _get_response
    response = wrapped_callback(request, *callback_args, **callback_kwargs)
  File "/Users/petergangmei/Developer/Projects/django/quiz /app/views.py", line 15, in home
    return render(request, 'home.html', {'quizzes': quizzes})
  File "/Users/petergangmei/Developer/Projects/django/quiz /venv/lib/python3.13/site-packages/django/shortcuts.py", line 25, in render
    content = loader.render_to_string(template_name, context, request, using=using)
  File "/Users/petergangmei/Developer/Projects/django/quiz /venv/lib/python3.13/site-packages/django/template/loader.py", line 62, in render_to_string
    return template.render(context, request)
           ~~~~~~~~~~~~~~~^^^^^^^^^^^^^^^^^^
  File "/Users/petergangmei/Developer/Projects/django/quiz /venv/lib/python3.13/site-packages/django/template/backends/django.py", line 107, in render
    return self.template.render(context)
           ~~~~~~~~~~~~~~~~~~~~^^^^^^^^^
  File "/Users/petergangmei/Developer/Projects/django/quiz /venv/lib/python3.13/site-packages/django/template/base.py", line 171, in render
    return self._render(context)
           ~~~~~~~~~~~~^^^^^^^^^
  File "/Users/petergangmei/Developer/Projects/django/quiz /venv/lib/python3.13/site-packages/django/template/base.py", line 163, in _render
    return self.nodelist.render(context)
           ~~~~~~~~~~~~~~~~~~~~^^^^^^^^^
  File "/Users/petergangmei/Developer/Projects/django/quiz /venv/lib/python3.13/site-packages/django/template/base.py", line 1008, in render
    return SafeString("".join([node.render_annotated(context) for node in self]))
                               ~~~~~~~~~~~~~~~~~~~~~^^^^^^^^^
  File "/Users/petergangmei/Developer/Projects/django/quiz /venv/lib/python3.13/site-packages/django/template/base.py", line 969, in render_annotated
    return self.render(context)
           ~~~~~~~~~~~^^^^^^^^^
  File "/Users/petergangmei/Developer/Projects/django/quiz /venv/lib/python3.13/site-packages/django/template/loader_tags.py", line 159, in render
    return compiled_parent._render(context)
           ~~~~~~~~~~~~~~~~~~~~~~~^^^^^^^^^
  File "/Users/petergangmei/Developer/Projects/django/quiz /venv/lib/python3.13/site-packages/django/template/base.py", line 163, in _render
    return self.nodelist.render(context)
           ~~~~~~~~~~~~~~~~~~~~^^^^^^^^^
  File "/Users/petergangmei/Developer/Projects/django/quiz /venv/lib/python3.13/site-packages/django/template/base.py", line 1008, in render
    return SafeString("".join([node.render_annotated(context) for node in self]))
                               ~~~~~~~~~~~~~~~~~~~~~^^^^^^^^^
  File "/Users/petergangmei/Developer/Projects/django/quiz /venv/lib/python3.13/site-packages/django/template/base.py", line 969, in render_annotated
    return self.render(context)
           ~~~~~~~~~~~^^^^^^^^^
  File "/Users/petergangmei/Developer/Projects/django/quiz /venv/lib/python3.13/site-packages/django/template/loader_tags.py", line 210, in render
    return template.render(context)
           ~~~~~~~~~~~~~~~^^^^^^^^^
  File "/Users/petergangmei/Developer/Projects/django/quiz /venv/lib/python3.13/site-packages/django/template/base.py", line 173, in render
    return self._render(context)
           ~~~~~~~~~~~~^^^^^^^^^
  File "/Users/petergangmei/Developer/Projects/django/quiz /venv/lib/python3.13/site-packages/django/template/base.py", line 163, in _render
    return self.nodelist.render(context)
           ~~~~~~~~~~~~~~~~~~~~^^^^^^^^^
  File "/Users/petergangmei/Developer/Projects/django/quiz /venv/lib/python3.13/site-packages/django/template/base.py", line 1008, in render
    return SafeString("".join([node.render_annotated(context) for node in self]))
                               ~~~~~~~~~~~~~~~~~~~~~^^^^^^^^^
  File "/Users/petergangmei/Developer/Projects/django/quiz /venv/lib/python3.13/site-packages/django/template/base.py", line 969, in render_annotated
    return self.render(context)
           ~~~~~~~~~~~^^^^^^^^^
  File "/Users/petergangmei/Developer/Projects/django/quiz /venv/lib/python3.13/site-packages/django/template/defaulttags.py", line 480, in render
    url = reverse(view_name, args=args, kwargs=kwargs, current_app=current_app)
  File "/Users/petergangmei/Developer/Projects/django/quiz /venv/lib/python3.13/site-packages/django/urls/base.py", line 82, in reverse
    raise NoReverseMatch("%s is not a registered namespace" % key)
django.urls.exceptions.NoReverseMatch: 'app' is not a registered namespace
ERROR 2025-03-28 07:28:26,079 basehttp 25044 6147371008 "GET / HTTP/1.1" 500 161454
ERROR 2025-03-28 07:29:01,163 log 27326 6200733696 Internal Server Error: /
Traceback (most recent call last):
  File "/Users/petergangmei/Developer/Projects/django/quiz /venv/lib/python3.13/site-packages/django/urls/base.py", line 71, in reverse
    extra, resolver = resolver.namespace_dict[ns]
                      ~~~~~~~~~~~~~~~~~~~~~~~^^^^
KeyError: 'app'

During handling of the above exception, another exception occurred:

Traceback (most recent call last):
  File "/Users/petergangmei/Developer/Projects/django/quiz /venv/lib/python3.13/site-packages/django/core/handlers/exception.py", line 55, in inner
    response = get_response(request)
  File "/Users/petergangmei/Developer/Projects/django/quiz /venv/lib/python3.13/site-packages/django/core/handlers/base.py", line 197, in _get_response
    response = wrapped_callback(request, *callback_args, **callback_kwargs)
  File "/Users/petergangmei/Developer/Projects/django/quiz /app/views.py", line 15, in home
    return render(request, 'home.html', {'quizzes': quizzes})
  File "/Users/petergangmei/Developer/Projects/django/quiz /venv/lib/python3.13/site-packages/django/shortcuts.py", line 25, in render
    content = loader.render_to_string(template_name, context, request, using=using)
  File "/Users/petergangmei/Developer/Projects/django/quiz /venv/lib/python3.13/site-packages/django/template/loader.py", line 62, in render_to_string
    return template.render(context, request)
           ~~~~~~~~~~~~~~~^^^^^^^^^^^^^^^^^^
  File "/Users/petergangmei/Developer/Projects/django/quiz /venv/lib/python3.13/site-packages/django/template/backends/django.py", line 107, in render
    return self.template.render(context)
           ~~~~~~~~~~~~~~~~~~~~^^^^^^^^^
  File "/Users/petergangmei/Developer/Projects/django/quiz /venv/lib/python3.13/site-packages/django/template/base.py", line 171, in render
    return self._render(context)
           ~~~~~~~~~~~~^^^^^^^^^
  File "/Users/petergangmei/Developer/Projects/django/quiz /venv/lib/python3.13/site-packages/django/template/base.py", line 163, in _render
    return self.nodelist.render(context)
           ~~~~~~~~~~~~~~~~~~~~^^^^^^^^^
  File "/Users/petergangmei/Developer/Projects/django/quiz /venv/lib/python3.13/site-packages/django/template/base.py", line 1008, in render
    return SafeString("".join([node.render_annotated(context) for node in self]))
                               ~~~~~~~~~~~~~~~~~~~~~^^^^^^^^^
  File "/Users/petergangmei/Developer/Projects/django/quiz /venv/lib/python3.13/site-packages/django/template/base.py", line 969, in render_annotated
    return self.render(context)
           ~~~~~~~~~~~^^^^^^^^^
  File "/Users/petergangmei/Developer/Projects/django/quiz /venv/lib/python3.13/site-packages/django/template/loader_tags.py", line 159, in render
    return compiled_parent._render(context)
           ~~~~~~~~~~~~~~~~~~~~~~~^^^^^^^^^
  File "/Users/petergangmei/Developer/Projects/django/quiz /venv/lib/python3.13/site-packages/django/template/base.py", line 163, in _render
    return self.nodelist.render(context)
           ~~~~~~~~~~~~~~~~~~~~^^^^^^^^^
  File "/Users/petergangmei/Developer/Projects/django/quiz /venv/lib/python3.13/site-packages/django/template/base.py", line 1008, in render
    return SafeString("".join([node.render_annotated(context) for node in self]))
                               ~~~~~~~~~~~~~~~~~~~~~^^^^^^^^^
  File "/Users/petergangmei/Developer/Projects/django/quiz /venv/lib/python3.13/site-packages/django/template/base.py", line 969, in render_annotated
    return self.render(context)
           ~~~~~~~~~~~^^^^^^^^^
  File "/Users/petergangmei/Developer/Projects/django/quiz /venv/lib/python3.13/site-packages/django/template/loader_tags.py", line 210, in render
    return template.render(context)
           ~~~~~~~~~~~~~~~^^^^^^^^^
  File "/Users/petergangmei/Developer/Projects/django/quiz /venv/lib/python3.13/site-packages/django/template/base.py", line 173, in render
    return self._render(context)
           ~~~~~~~~~~~~^^^^^^^^^
  File "/Users/petergangmei/Developer/Projects/django/quiz /venv/lib/python3.13/site-packages/django/template/base.py", line 163, in _render
    return self.nodelist.render(context)
           ~~~~~~~~~~~~~~~~~~~~^^^^^^^^^
  File "/Users/petergangmei/Developer/Projects/django/quiz /venv/lib/python3.13/site-packages/django/template/base.py", line 1008, in render
    return SafeString("".join([node.render_annotated(context) for node in self]))
                               ~~~~~~~~~~~~~~~~~~~~~^^^^^^^^^
  File "/Users/petergangmei/Developer/Projects/django/quiz /venv/lib/python3.13/site-packages/django/template/base.py", line 969, in render_annotated
    return self.render(context)
           ~~~~~~~~~~~^^^^^^^^^
  File "/Users/petergangmei/Developer/Projects/django/quiz /venv/lib/python3.13/site-packages/django/template/defaulttags.py", line 480, in render
    url = reverse(view_name, args=args, kwargs=kwargs, current_app=current_app)
  File "/Users/petergangmei/Developer/Projects/django/quiz /venv/lib/python3.13/site-packages/django/urls/base.py", line 82, in reverse
    raise NoReverseMatch("%s is not a registered namespace" % key)
django.urls.exceptions.NoReverseMatch: 'app' is not a registered namespace
ERROR 2025-03-28 07:29:01,168 basehttp 27326 6200733696 "GET / HTTP/1.1" 500 161454
ERROR 2025-03-28 07:29:05,827 log 27326 6200733696 Internal Server Error: /
Traceback (most recent call last):
  File "/Users/petergangmei/Developer/Projects/django/quiz /venv/lib/python3.13/site-packages/django/urls/base.py", line 71, in reverse
    extra, resolver = resolver.namespace_dict[ns]
                      ~~~~~~~~~~~~~~~~~~~~~~~^^^^
KeyError: 'app'

During handling of the above exception, another exception occurred:

Traceback (most recent call last):
  File "/Users/petergangmei/Developer/Projects/django/quiz /venv/lib/python3.13/site-packages/django/core/handlers/exception.py", line 55, in inner
    response = get_response(request)
  File "/Users/petergangmei/Developer/Projects/django/quiz /venv/lib/python3.13/site-packages/django/core/handlers/base.py", line 197, in _get_response
    response = wrapped_callback(request, *callback_args, **callback_kwargs)
  File "/Users/petergangmei/Developer/Projects/django/quiz /app/views.py", line 15, in home
    return render(request, 'home.html', {'quizzes': quizzes})
  File "/Users/petergangmei/Developer/Projects/django/quiz /venv/lib/python3.13/site-packages/django/shortcuts.py", line 25, in render
    content = loader.render_to_string(template_name, context, request, using=using)
  File "/Users/petergangmei/Developer/Projects/django/quiz /venv/lib/python3.13/site-packages/django/template/loader.py", line 62, in render_to_string
    return template.render(context, request)
           ~~~~~~~~~~~~~~~^^^^^^^^^^^^^^^^^^
  File "/Users/petergangmei/Developer/Projects/django/quiz /venv/lib/python3.13/site-packages/django/template/backends/django.py", line 107, in render
    return self.template.render(context)
           ~~~~~~~~~~~~~~~~~~~~^^^^^^^^^
  File "/Users/petergangmei/Developer/Projects/django/quiz /venv/lib/python3.13/site-packages/django/template/base.py", line 171, in render
    return self._render(context)
           ~~~~~~~~~~~~^^^^^^^^^
  File "/Users/petergangmei/Developer/Projects/django/quiz /venv/lib/python3.13/site-packages/django/template/base.py", line 163, in _render
    return self.nodelist.render(context)
           ~~~~~~~~~~~~~~~~~~~~^^^^^^^^^
  File "/Users/petergangmei/Developer/Projects/django/quiz /venv/lib/python3.13/site-packages/django/template/base.py", line 1008, in render
    return SafeString("".join([node.render_annotated(context) for node in self]))
                               ~~~~~~~~~~~~~~~~~~~~~^^^^^^^^^
  File "/Users/petergangmei/Developer/Projects/django/quiz /venv/lib/python3.13/site-packages/django/template/base.py", line 969, in render_annotated
    return self.render(context)
           ~~~~~~~~~~~^^^^^^^^^
  File "/Users/petergangmei/Developer/Projects/django/quiz /venv/lib/python3.13/site-packages/django/template/loader_tags.py", line 159, in render
    return compiled_parent._render(context)
           ~~~~~~~~~~~~~~~~~~~~~~~^^^^^^^^^
  File "/Users/petergangmei/Developer/Projects/django/quiz /venv/lib/python3.13/site-packages/django/template/base.py", line 163, in _render
    return self.nodelist.render(context)
           ~~~~~~~~~~~~~~~~~~~~^^^^^^^^^
  File "/Users/petergangmei/Developer/Projects/django/quiz /venv/lib/python3.13/site-packages/django/template/base.py", line 1008, in render
    return SafeString("".join([node.render_annotated(context) for node in self]))
                               ~~~~~~~~~~~~~~~~~~~~~^^^^^^^^^
  File "/Users/petergangmei/Developer/Projects/django/quiz /venv/lib/python3.13/site-packages/django/template/base.py", line 969, in render_annotated
    return self.render(context)
           ~~~~~~~~~~~^^^^^^^^^
  File "/Users/petergangmei/Developer/Projects/django/quiz /venv/lib/python3.13/site-packages/django/template/loader_tags.py", line 210, in render
    return template.render(context)
           ~~~~~~~~~~~~~~~^^^^^^^^^
  File "/Users/petergangmei/Developer/Projects/django/quiz /venv/lib/python3.13/site-packages/django/template/base.py", line 173, in render
    return self._render(context)
           ~~~~~~~~~~~~^^^^^^^^^
  File "/Users/petergangmei/Developer/Projects/django/quiz /venv/lib/python3.13/site-packages/django/template/base.py", line 163, in _render
    return self.nodelist.render(context)
           ~~~~~~~~~~~~~~~~~~~~^^^^^^^^^
  File "/Users/petergangmei/Developer/Projects/django/quiz /venv/lib/python3.13/site-packages/django/template/base.py", line 1008, in render
    return SafeString("".join([node.render_annotated(context) for node in self]))
                               ~~~~~~~~~~~~~~~~~~~~~^^^^^^^^^
  File "/Users/petergangmei/Developer/Projects/django/quiz /venv/lib/python3.13/site-packages/django/template/base.py", line 969, in render_annotated
    return self.render(context)
           ~~~~~~~~~~~^^^^^^^^^
  File "/Users/petergangmei/Developer/Projects/django/quiz /venv/lib/python3.13/site-packages/django/template/defaulttags.py", line 480, in render
    url = reverse(view_name, args=args, kwargs=kwargs, current_app=current_app)
  File "/Users/petergangmei/Developer/Projects/django/quiz /venv/lib/python3.13/site-packages/django/urls/base.py", line 82, in reverse
    raise NoReverseMatch("%s is not a registered namespace" % key)
django.urls.exceptions.NoReverseMatch: 'app' is not a registered namespace
ERROR 2025-03-28 07:29:05,830 basehttp 27326 6200733696 "GET / HTTP/1.1" 500 161454
ERROR 2025-03-28 07:29:52,941 log 27404 6199980032 Internal Server Error: /
Traceback (most recent call last):
  File "/Users/petergangmei/Developer/Projects/django/quiz /venv/lib/python3.13/site-packages/django/urls/base.py", line 71, in reverse
    extra, resolver = resolver.namespace_dict[ns]
                      ~~~~~~~~~~~~~~~~~~~~~~~^^^^
KeyError: 'app'

During handling of the above exception, another exception occurred:

Traceback (most recent call last):
  File "/Users/petergangmei/Developer/Projects/django/quiz /venv/lib/python3.13/site-packages/django/core/handlers/exception.py", line 55, in inner
    response = get_response(request)
  File "/Users/petergangmei/Developer/Projects/django/quiz /venv/lib/python3.13/site-packages/django/core/handlers/base.py", line 197, in _get_response
    response = wrapped_callback(request, *callback_args, **callback_kwargs)
  File "/Users/petergangmei/Developer/Projects/django/quiz /app/views.py", line 15, in home
    return render(request, 'home.html', {'quizzes': quizzes})
  File "/Users/petergangmei/Developer/Projects/django/quiz /venv/lib/python3.13/site-packages/django/shortcuts.py", line 25, in render
    content = loader.render_to_string(template_name, context, request, using=using)
  File "/Users/petergangmei/Developer/Projects/django/quiz /venv/lib/python3.13/site-packages/django/template/loader.py", line 62, in render_to_string
    return template.render(context, request)
           ~~~~~~~~~~~~~~~^^^^^^^^^^^^^^^^^^
  File "/Users/petergangmei/Developer/Projects/django/quiz /venv/lib/python3.13/site-packages/django/template/backends/django.py", line 107, in render
    return self.template.render(context)
           ~~~~~~~~~~~~~~~~~~~~^^^^^^^^^
  File "/Users/petergangmei/Developer/Projects/django/quiz /venv/lib/python3.13/site-packages/django/template/base.py", line 171, in render
    return self._render(context)
           ~~~~~~~~~~~~^^^^^^^^^
  File "/Users/petergangmei/Developer/Projects/django/quiz /venv/lib/python3.13/site-packages/django/template/base.py", line 163, in _render
    return self.nodelist.render(context)
           ~~~~~~~~~~~~~~~~~~~~^^^^^^^^^
  File "/Users/petergangmei/Developer/Projects/django/quiz /venv/lib/python3.13/site-packages/django/template/base.py", line 1008, in render
    return SafeString("".join([node.render_annotated(context) for node in self]))
                               ~~~~~~~~~~~~~~~~~~~~~^^^^^^^^^
  File "/Users/petergangmei/Developer/Projects/django/quiz /venv/lib/python3.13/site-packages/django/template/base.py", line 969, in render_annotated
    return self.render(context)
           ~~~~~~~~~~~^^^^^^^^^
  File "/Users/petergangmei/Developer/Projects/django/quiz /venv/lib/python3.13/site-packages/django/template/loader_tags.py", line 159, in render
    return compiled_parent._render(context)
           ~~~~~~~~~~~~~~~~~~~~~~~^^^^^^^^^
  File "/Users/petergangmei/Developer/Projects/django/quiz /venv/lib/python3.13/site-packages/django/template/base.py", line 163, in _render
    return self.nodelist.render(context)
           ~~~~~~~~~~~~~~~~~~~~^^^^^^^^^
  File "/Users/petergangmei/Developer/Projects/django/quiz /venv/lib/python3.13/site-packages/django/template/base.py", line 1008, in render
    return SafeString("".join([node.render_annotated(context) for node in self]))
                               ~~~~~~~~~~~~~~~~~~~~~^^^^^^^^^
  File "/Users/petergangmei/Developer/Projects/django/quiz /venv/lib/python3.13/site-packages/django/template/base.py", line 969, in render_annotated
    return self.render(context)
           ~~~~~~~~~~~^^^^^^^^^
  File "/Users/petergangmei/Developer/Projects/django/quiz /venv/lib/python3.13/site-packages/django/template/loader_tags.py", line 210, in render
    return template.render(context)
           ~~~~~~~~~~~~~~~^^^^^^^^^
  File "/Users/petergangmei/Developer/Projects/django/quiz /venv/lib/python3.13/site-packages/django/template/base.py", line 173, in render
    return self._render(context)
           ~~~~~~~~~~~~^^^^^^^^^
  File "/Users/petergangmei/Developer/Projects/django/quiz /venv/lib/python3.13/site-packages/django/template/base.py", line 163, in _render
    return self.nodelist.render(context)
           ~~~~~~~~~~~~~~~~~~~~^^^^^^^^^
  File "/Users/petergangmei/Developer/Projects/django/quiz /venv/lib/python3.13/site-packages/django/template/base.py", line 1008, in render
    return SafeString("".join([node.render_annotated(context) for node in self]))
                               ~~~~~~~~~~~~~~~~~~~~~^^^^^^^^^
  File "/Users/petergangmei/Developer/Projects/django/quiz /venv/lib/python3.13/site-packages/django/template/base.py", line 969, in render_annotated
    return self.render(context)
           ~~~~~~~~~~~^^^^^^^^^
  File "/Users/petergangmei/Developer/Projects/django/quiz /venv/lib/python3.13/site-packages/django/template/defaulttags.py", line 480, in render
    url = reverse(view_name, args=args, kwargs=kwargs, current_app=current_app)
  File "/Users/petergangmei/Developer/Projects/django/quiz /venv/lib/python3.13/site-packages/django/urls/base.py", line 82, in reverse
    raise NoReverseMatch("%s is not a registered namespace" % key)
django.urls.exceptions.NoReverseMatch: 'app' is not a registered namespace
ERROR 2025-03-28 07:29:52,946 basehttp 27404 6199980032 "GET / HTTP/1.1" 500 161454
ERROR 2025-03-28 07:29:54,473 log 27404 6216806400 Internal Server Error: /
Traceback (most recent call last):
  File "/Users/petergangmei/Developer/Projects/django/quiz /venv/lib/python3.13/site-packages/django/urls/base.py", line 71, in reverse
    extra, resolver = resolver.namespace_dict[ns]
                      ~~~~~~~~~~~~~~~~~~~~~~~^^^^
KeyError: 'app'

During handling of the above exception, another exception occurred:

Traceback (most recent call last):
  File "/Users/petergangmei/Developer/Projects/django/quiz /venv/lib/python3.13/site-packages/django/core/handlers/exception.py", line 55, in inner
    response = get_response(request)
  File "/Users/petergangmei/Developer/Projects/django/quiz /venv/lib/python3.13/site-packages/django/core/handlers/base.py", line 197, in _get_response
    response = wrapped_callback(request, *callback_args, **callback_kwargs)
  File "/Users/petergangmei/Developer/Projects/django/quiz /app/views.py", line 15, in home
    return render(request, 'home.html', {'quizzes': quizzes})
  File "/Users/petergangmei/Developer/Projects/django/quiz /venv/lib/python3.13/site-packages/django/shortcuts.py", line 25, in render
    content = loader.render_to_string(template_name, context, request, using=using)
  File "/Users/petergangmei/Developer/Projects/django/quiz /venv/lib/python3.13/site-packages/django/template/loader.py", line 62, in render_to_string
    return template.render(context, request)
           ~~~~~~~~~~~~~~~^^^^^^^^^^^^^^^^^^
  File "/Users/petergangmei/Developer/Projects/django/quiz /venv/lib/python3.13/site-packages/django/template/backends/django.py", line 107, in render
    return self.template.render(context)
           ~~~~~~~~~~~~~~~~~~~~^^^^^^^^^
  File "/Users/petergangmei/Developer/Projects/django/quiz /venv/lib/python3.13/site-packages/django/template/base.py", line 171, in render
    return self._render(context)
           ~~~~~~~~~~~~^^^^^^^^^
  File "/Users/petergangmei/Developer/Projects/django/quiz /venv/lib/python3.13/site-packages/django/template/base.py", line 163, in _render
    return self.nodelist.render(context)
           ~~~~~~~~~~~~~~~~~~~~^^^^^^^^^
  File "/Users/petergangmei/Developer/Projects/django/quiz /venv/lib/python3.13/site-packages/django/template/base.py", line 1008, in render
    return SafeString("".join([node.render_annotated(context) for node in self]))
                               ~~~~~~~~~~~~~~~~~~~~~^^^^^^^^^
  File "/Users/petergangmei/Developer/Projects/django/quiz /venv/lib/python3.13/site-packages/django/template/base.py", line 969, in render_annotated
    return self.render(context)
           ~~~~~~~~~~~^^^^^^^^^
  File "/Users/petergangmei/Developer/Projects/django/quiz /venv/lib/python3.13/site-packages/django/template/loader_tags.py", line 159, in render
    return compiled_parent._render(context)
           ~~~~~~~~~~~~~~~~~~~~~~~^^^^^^^^^
  File "/Users/petergangmei/Developer/Projects/django/quiz /venv/lib/python3.13/site-packages/django/template/base.py", line 163, in _render
    return self.nodelist.render(context)
           ~~~~~~~~~~~~~~~~~~~~^^^^^^^^^
  File "/Users/petergangmei/Developer/Projects/django/quiz /venv/lib/python3.13/site-packages/django/template/base.py", line 1008, in render
    return SafeString("".join([node.render_annotated(context) for node in self]))
                               ~~~~~~~~~~~~~~~~~~~~~^^^^^^^^^
  File "/Users/petergangmei/Developer/Projects/django/quiz /venv/lib/python3.13/site-packages/django/template/base.py", line 969, in render_annotated
    return self.render(context)
           ~~~~~~~~~~~^^^^^^^^^
  File "/Users/petergangmei/Developer/Projects/django/quiz /venv/lib/python3.13/site-packages/django/template/loader_tags.py", line 210, in render
    return template.render(context)
           ~~~~~~~~~~~~~~~^^^^^^^^^
  File "/Users/petergangmei/Developer/Projects/django/quiz /venv/lib/python3.13/site-packages/django/template/base.py", line 173, in render
    return self._render(context)
           ~~~~~~~~~~~~^^^^^^^^^
  File "/Users/petergangmei/Developer/Projects/django/quiz /venv/lib/python3.13/site-packages/django/template/base.py", line 163, in _render
    return self.nodelist.render(context)
           ~~~~~~~~~~~~~~~~~~~~^^^^^^^^^
  File "/Users/petergangmei/Developer/Projects/django/quiz /venv/lib/python3.13/site-packages/django/template/base.py", line 1008, in render
    return SafeString("".join([node.render_annotated(context) for node in self]))
                               ~~~~~~~~~~~~~~~~~~~~~^^^^^^^^^
  File "/Users/petergangmei/Developer/Projects/django/quiz /venv/lib/python3.13/site-packages/django/template/base.py", line 969, in render_annotated
    return self.render(context)
           ~~~~~~~~~~~^^^^^^^^^
  File "/Users/petergangmei/Developer/Projects/django/quiz /venv/lib/python3.13/site-packages/django/template/defaulttags.py", line 480, in render
    url = reverse(view_name, args=args, kwargs=kwargs, current_app=current_app)
  File "/Users/petergangmei/Developer/Projects/django/quiz /venv/lib/python3.13/site-packages/django/urls/base.py", line 82, in reverse
    raise NoReverseMatch("%s is not a registered namespace" % key)
django.urls.exceptions.NoReverseMatch: 'app' is not a registered namespace
ERROR 2025-03-28 07:29:54,477 basehttp 27404 6216806400 "GET / HTTP/1.1" 500 161454
ERROR 2025-03-28 07:37:48,361 log 27421 6146781184 Internal Server Error: /
Traceback (most recent call last):
  File "/Users/petergangmei/Developer/Projects/django/quiz /venv/lib/python3.13/site-packages/django/urls/base.py", line 71, in reverse
    extra, resolver = resolver.namespace_dict[ns]
                      ~~~~~~~~~~~~~~~~~~~~~~~^^^^
KeyError: 'app'

During handling of the above exception, another exception occurred:

Traceback (most recent call last):
  File "/Users/petergangmei/Developer/Projects/django/quiz /venv/lib/python3.13/site-packages/django/core/handlers/exception.py", line 55, in inner
    response = get_response(request)
  File "/Users/petergangmei/Developer/Projects/django/quiz /venv/lib/python3.13/site-packages/django/core/handlers/base.py", line 197, in _get_response
    response = wrapped_callback(request, *callback_args, **callback_kwargs)
  File "/Users/petergangmei/Developer/Projects/django/quiz /app/views.py", line 15, in home
    return render(request, 'home.html', {'quizzes': quizzes})
  File "/Users/petergangmei/Developer/Projects/django/quiz /venv/lib/python3.13/site-packages/django/shortcuts.py", line 25, in render
    content = loader.render_to_string(template_name, context, request, using=using)
  File "/Users/petergangmei/Developer/Projects/django/quiz /venv/lib/python3.13/site-packages/django/template/loader.py", line 62, in render_to_string
    return template.render(context, request)
           ~~~~~~~~~~~~~~~^^^^^^^^^^^^^^^^^^
  File "/Users/petergangmei/Developer/Projects/django/quiz /venv/lib/python3.13/site-packages/django/template/backends/django.py", line 107, in render
    return self.template.render(context)
           ~~~~~~~~~~~~~~~~~~~~^^^^^^^^^
  File "/Users/petergangmei/Developer/Projects/django/quiz /venv/lib/python3.13/site-packages/django/template/base.py", line 171, in render
    return self._render(context)
           ~~~~~~~~~~~~^^^^^^^^^
  File "/Users/petergangmei/Developer/Projects/django/quiz /venv/lib/python3.13/site-packages/django/template/base.py", line 163, in _render
    return self.nodelist.render(context)
           ~~~~~~~~~~~~~~~~~~~~^^^^^^^^^
  File "/Users/petergangmei/Developer/Projects/django/quiz /venv/lib/python3.13/site-packages/django/template/base.py", line 1008, in render
    return SafeString("".join([node.render_annotated(context) for node in self]))
                               ~~~~~~~~~~~~~~~~~~~~~^^^^^^^^^
  File "/Users/petergangmei/Developer/Projects/django/quiz /venv/lib/python3.13/site-packages/django/template/base.py", line 969, in render_annotated
    return self.render(context)
           ~~~~~~~~~~~^^^^^^^^^
  File "/Users/petergangmei/Developer/Projects/django/quiz /venv/lib/python3.13/site-packages/django/template/loader_tags.py", line 159, in render
    return compiled_parent._render(context)
           ~~~~~~~~~~~~~~~~~~~~~~~^^^^^^^^^
  File "/Users/petergangmei/Developer/Projects/django/quiz /venv/lib/python3.13/site-packages/django/template/base.py", line 163, in _render
    return self.nodelist.render(context)
           ~~~~~~~~~~~~~~~~~~~~^^^^^^^^^
  File "/Users/petergangmei/Developer/Projects/django/quiz /venv/lib/python3.13/site-packages/django/template/base.py", line 1008, in render
    return SafeString("".join([node.render_annotated(context) for node in self]))
                               ~~~~~~~~~~~~~~~~~~~~~^^^^^^^^^
  File "/Users/petergangmei/Developer/Projects/django/quiz /venv/lib/python3.13/site-packages/django/template/base.py", line 969, in render_annotated
    return self.render(context)
           ~~~~~~~~~~~^^^^^^^^^
  File "/Users/petergangmei/Developer/Projects/django/quiz /venv/lib/python3.13/site-packages/django/template/loader_tags.py", line 210, in render
    return template.render(context)
           ~~~~~~~~~~~~~~~^^^^^^^^^
  File "/Users/petergangmei/Developer/Projects/django/quiz /venv/lib/python3.13/site-packages/django/template/base.py", line 173, in render
    return self._render(context)
           ~~~~~~~~~~~~^^^^^^^^^
  File "/Users/petergangmei/Developer/Projects/django/quiz /venv/lib/python3.13/site-packages/django/template/base.py", line 163, in _render
    return self.nodelist.render(context)
           ~~~~~~~~~~~~~~~~~~~~^^^^^^^^^
  File "/Users/petergangmei/Developer/Projects/django/quiz /venv/lib/python3.13/site-packages/django/template/base.py", line 1008, in render
    return SafeString("".join([node.render_annotated(context) for node in self]))
                               ~~~~~~~~~~~~~~~~~~~~~^^^^^^^^^
  File "/Users/petergangmei/Developer/Projects/django/quiz /venv/lib/python3.13/site-packages/django/template/base.py", line 969, in render_annotated
    return self.render(context)
           ~~~~~~~~~~~^^^^^^^^^
  File "/Users/petergangmei/Developer/Projects/django/quiz /venv/lib/python3.13/site-packages/django/template/defaulttags.py", line 480, in render
    url = reverse(view_name, args=args, kwargs=kwargs, current_app=current_app)
  File "/Users/petergangmei/Developer/Projects/django/quiz /venv/lib/python3.13/site-packages/django/urls/base.py", line 82, in reverse
    raise NoReverseMatch("%s is not a registered namespace" % key)
django.urls.exceptions.NoReverseMatch: 'app' is not a registered namespace
ERROR 2025-03-28 07:37:48,370 basehttp 27421 6146781184 "GET / HTTP/1.1" 500 162187
ERROR 2025-03-28 07:37:53,621 log 27421 6129954816 Internal Server Error: /
Traceback (most recent call last):
  File "/Users/petergangmei/Developer/Projects/django/quiz /venv/lib/python3.13/site-packages/django/urls/base.py", line 71, in reverse
    extra, resolver = resolver.namespace_dict[ns]
                      ~~~~~~~~~~~~~~~~~~~~~~~^^^^
KeyError: 'app'

During handling of the above exception, another exception occurred:

Traceback (most recent call last):
  File "/Users/petergangmei/Developer/Projects/django/quiz /venv/lib/python3.13/site-packages/django/core/handlers/exception.py", line 55, in inner
    response = get_response(request)
  File "/Users/petergangmei/Developer/Projects/django/quiz /venv/lib/python3.13/site-packages/django/core/handlers/base.py", line 197, in _get_response
    response = wrapped_callback(request, *callback_args, **callback_kwargs)
  File "/Users/petergangmei/Developer/Projects/django/quiz /app/views.py", line 15, in home
    return render(request, 'home.html', {'quizzes': quizzes})
  File "/Users/petergangmei/Developer/Projects/django/quiz /venv/lib/python3.13/site-packages/django/shortcuts.py", line 25, in render
    content = loader.render_to_string(template_name, context, request, using=using)
  File "/Users/petergangmei/Developer/Projects/django/quiz /venv/lib/python3.13/site-packages/django/template/loader.py", line 62, in render_to_string
    return template.render(context, request)
           ~~~~~~~~~~~~~~~^^^^^^^^^^^^^^^^^^
  File "/Users/petergangmei/Developer/Projects/django/quiz /venv/lib/python3.13/site-packages/django/template/backends/django.py", line 107, in render
    return self.template.render(context)
           ~~~~~~~~~~~~~~~~~~~~^^^^^^^^^
  File "/Users/petergangmei/Developer/Projects/django/quiz /venv/lib/python3.13/site-packages/django/template/base.py", line 171, in render
    return self._render(context)
           ~~~~~~~~~~~~^^^^^^^^^
  File "/Users/petergangmei/Developer/Projects/django/quiz /venv/lib/python3.13/site-packages/django/template/base.py", line 163, in _render
    return self.nodelist.render(context)
           ~~~~~~~~~~~~~~~~~~~~^^^^^^^^^
  File "/Users/petergangmei/Developer/Projects/django/quiz /venv/lib/python3.13/site-packages/django/template/base.py", line 1008, in render
    return SafeString("".join([node.render_annotated(context) for node in self]))
                               ~~~~~~~~~~~~~~~~~~~~~^^^^^^^^^
  File "/Users/petergangmei/Developer/Projects/django/quiz /venv/lib/python3.13/site-packages/django/template/base.py", line 969, in render_annotated
    return self.render(context)
           ~~~~~~~~~~~^^^^^^^^^
  File "/Users/petergangmei/Developer/Projects/django/quiz /venv/lib/python3.13/site-packages/django/template/loader_tags.py", line 159, in render
    return compiled_parent._render(context)
           ~~~~~~~~~~~~~~~~~~~~~~~^^^^^^^^^
  File "/Users/petergangmei/Developer/Projects/django/quiz /venv/lib/python3.13/site-packages/django/template/base.py", line 163, in _render
    return self.nodelist.render(context)
           ~~~~~~~~~~~~~~~~~~~~^^^^^^^^^
  File "/Users/petergangmei/Developer/Projects/django/quiz /venv/lib/python3.13/site-packages/django/template/base.py", line 1008, in render
    return SafeString("".join([node.render_annotated(context) for node in self]))
                               ~~~~~~~~~~~~~~~~~~~~~^^^^^^^^^
  File "/Users/petergangmei/Developer/Projects/django/quiz /venv/lib/python3.13/site-packages/django/template/base.py", line 969, in render_annotated
    return self.render(context)
           ~~~~~~~~~~~^^^^^^^^^
  File "/Users/petergangmei/Developer/Projects/django/quiz /venv/lib/python3.13/site-packages/django/template/loader_tags.py", line 210, in render
    return template.render(context)
           ~~~~~~~~~~~~~~~^^^^^^^^^
  File "/Users/petergangmei/Developer/Projects/django/quiz /venv/lib/python3.13/site-packages/django/template/base.py", line 173, in render
    return self._render(context)
           ~~~~~~~~~~~~^^^^^^^^^
  File "/Users/petergangmei/Developer/Projects/django/quiz /venv/lib/python3.13/site-packages/django/template/base.py", line 163, in _render
    return self.nodelist.render(context)
           ~~~~~~~~~~~~~~~~~~~~^^^^^^^^^
  File "/Users/petergangmei/Developer/Projects/django/quiz /venv/lib/python3.13/site-packages/django/template/base.py", line 1008, in render
    return SafeString("".join([node.render_annotated(context) for node in self]))
                               ~~~~~~~~~~~~~~~~~~~~~^^^^^^^^^
  File "/Users/petergangmei/Developer/Projects/django/quiz /venv/lib/python3.13/site-packages/django/template/base.py", line 969, in render_annotated
    return self.render(context)
           ~~~~~~~~~~~^^^^^^^^^
  File "/Users/petergangmei/Developer/Projects/django/quiz /venv/lib/python3.13/site-packages/django/template/defaulttags.py", line 480, in render
    url = reverse(view_name, args=args, kwargs=kwargs, current_app=current_app)
  File "/Users/petergangmei/Developer/Projects/django/quiz /venv/lib/python3.13/site-packages/django/urls/base.py", line 82, in reverse
    raise NoReverseMatch("%s is not a registered namespace" % key)
django.urls.exceptions.NoReverseMatch: 'app' is not a registered namespace
ERROR 2025-03-28 07:37:53,625 basehttp 27421 6129954816 "GET / HTTP/1.1" 500 161454
ERROR 2025-03-28 07:38:02,070 log 27421 6146781184 Internal Server Error: /
Traceback (most recent call last):
  File "/Users/petergangmei/Developer/Projects/django/quiz /venv/lib/python3.13/site-packages/django/urls/base.py", line 71, in reverse
    extra, resolver = resolver.namespace_dict[ns]
                      ~~~~~~~~~~~~~~~~~~~~~~~^^^^
KeyError: 'app'

During handling of the above exception, another exception occurred:

Traceback (most recent call last):
  File "/Users/petergangmei/Developer/Projects/django/quiz /venv/lib/python3.13/site-packages/django/core/handlers/exception.py", line 55, in inner
    response = get_response(request)
  File "/Users/petergangmei/Developer/Projects/django/quiz /venv/lib/python3.13/site-packages/django/core/handlers/base.py", line 197, in _get_response
    response = wrapped_callback(request, *callback_args, **callback_kwargs)
  File "/Users/petergangmei/Developer/Projects/django/quiz /app/views.py", line 15, in home
    return render(request, 'home.html', {'quizzes': quizzes})
  File "/Users/petergangmei/Developer/Projects/django/quiz /venv/lib/python3.13/site-packages/django/shortcuts.py", line 25, in render
    content = loader.render_to_string(template_name, context, request, using=using)
  File "/Users/petergangmei/Developer/Projects/django/quiz /venv/lib/python3.13/site-packages/django/template/loader.py", line 62, in render_to_string
    return template.render(context, request)
           ~~~~~~~~~~~~~~~^^^^^^^^^^^^^^^^^^
  File "/Users/petergangmei/Developer/Projects/django/quiz /venv/lib/python3.13/site-packages/django/template/backends/django.py", line 107, in render
    return self.template.render(context)
           ~~~~~~~~~~~~~~~~~~~~^^^^^^^^^
  File "/Users/petergangmei/Developer/Projects/django/quiz /venv/lib/python3.13/site-packages/django/template/base.py", line 171, in render
    return self._render(context)
           ~~~~~~~~~~~~^^^^^^^^^
  File "/Users/petergangmei/Developer/Projects/django/quiz /venv/lib/python3.13/site-packages/django/template/base.py", line 163, in _render
    return self.nodelist.render(context)
           ~~~~~~~~~~~~~~~~~~~~^^^^^^^^^
  File "/Users/petergangmei/Developer/Projects/django/quiz /venv/lib/python3.13/site-packages/django/template/base.py", line 1008, in render
    return SafeString("".join([node.render_annotated(context) for node in self]))
                               ~~~~~~~~~~~~~~~~~~~~~^^^^^^^^^
  File "/Users/petergangmei/Developer/Projects/django/quiz /venv/lib/python3.13/site-packages/django/template/base.py", line 969, in render_annotated
    return self.render(context)
           ~~~~~~~~~~~^^^^^^^^^
  File "/Users/petergangmei/Developer/Projects/django/quiz /venv/lib/python3.13/site-packages/django/template/loader_tags.py", line 159, in render
    return compiled_parent._render(context)
           ~~~~~~~~~~~~~~~~~~~~~~~^^^^^^^^^
  File "/Users/petergangmei/Developer/Projects/django/quiz /venv/lib/python3.13/site-packages/django/template/base.py", line 163, in _render
    return self.nodelist.render(context)
           ~~~~~~~~~~~~~~~~~~~~^^^^^^^^^
  File "/Users/petergangmei/Developer/Projects/django/quiz /venv/lib/python3.13/site-packages/django/template/base.py", line 1008, in render
    return SafeString("".join([node.render_annotated(context) for node in self]))
                               ~~~~~~~~~~~~~~~~~~~~~^^^^^^^^^
  File "/Users/petergangmei/Developer/Projects/django/quiz /venv/lib/python3.13/site-packages/django/template/base.py", line 969, in render_annotated
    return self.render(context)
           ~~~~~~~~~~~^^^^^^^^^
  File "/Users/petergangmei/Developer/Projects/django/quiz /venv/lib/python3.13/site-packages/django/template/loader_tags.py", line 210, in render
    return template.render(context)
           ~~~~~~~~~~~~~~~^^^^^^^^^
  File "/Users/petergangmei/Developer/Projects/django/quiz /venv/lib/python3.13/site-packages/django/template/base.py", line 173, in render
    return self._render(context)
           ~~~~~~~~~~~~^^^^^^^^^
  File "/Users/petergangmei/Developer/Projects/django/quiz /venv/lib/python3.13/site-packages/django/template/base.py", line 163, in _render
    return self.nodelist.render(context)
           ~~~~~~~~~~~~~~~~~~~~^^^^^^^^^
  File "/Users/petergangmei/Developer/Projects/django/quiz /venv/lib/python3.13/site-packages/django/template/base.py", line 1008, in render
    return SafeString("".join([node.render_annotated(context) for node in self]))
                               ~~~~~~~~~~~~~~~~~~~~~^^^^^^^^^
  File "/Users/petergangmei/Developer/Projects/django/quiz /venv/lib/python3.13/site-packages/django/template/base.py", line 969, in render_annotated
    return self.render(context)
           ~~~~~~~~~~~^^^^^^^^^
  File "/Users/petergangmei/Developer/Projects/django/quiz /venv/lib/python3.13/site-packages/django/template/defaulttags.py", line 480, in render
    url = reverse(view_name, args=args, kwargs=kwargs, current_app=current_app)
  File "/Users/petergangmei/Developer/Projects/django/quiz /venv/lib/python3.13/site-packages/django/urls/base.py", line 82, in reverse
    raise NoReverseMatch("%s is not a registered namespace" % key)
django.urls.exceptions.NoReverseMatch: 'app' is not a registered namespace
ERROR 2025-03-28 07:38:02,073 basehttp 27421 6146781184 "GET / HTTP/1.1" 500 162452
ERROR 2025-03-28 07:46:08,306 log 27421 6180433920 Internal Server Error: /quiz/1/start/
Traceback (most recent call last):
  File "/Users/petergangmei/Developer/Projects/django/quiz /venv/lib/python3.13/site-packages/django/core/handlers/exception.py", line 55, in inner
    response = get_response(request)
  File "/Users/petergangmei/Developer/Projects/django/quiz /venv/lib/python3.13/site-packages/django/core/handlers/base.py", line 197, in _get_response
    response = wrapped_callback(request, *callback_args, **callback_kwargs)
  File "/Users/petergangmei/Developer/Projects/django/quiz /app/utils.py", line 35, in wrapped_view
    return view_func(request, *args, **kwargs)
  File "/Users/petergangmei/Developer/Projects/django/quiz /app/views.py", line 42, in quiz_start
    return render(request, 'app/assessment_instructions.html', {
        'user_quiz': user_quiz,
        'quiz': quiz,
        'token': user_quiz.access_token
    })
  File "/Users/petergangmei/Developer/Projects/django/quiz /venv/lib/python3.13/site-packages/django/shortcuts.py", line 25, in render
    content = loader.render_to_string(template_name, context, request, using=using)
  File "/Users/petergangmei/Developer/Projects/django/quiz /venv/lib/python3.13/site-packages/django/template/loader.py", line 62, in render_to_string
    return template.render(context, request)
           ~~~~~~~~~~~~~~~^^^^^^^^^^^^^^^^^^
  File "/Users/petergangmei/Developer/Projects/django/quiz /venv/lib/python3.13/site-packages/django/template/backends/django.py", line 107, in render
    return self.template.render(context)
           ~~~~~~~~~~~~~~~~~~~~^^^^^^^^^
  File "/Users/petergangmei/Developer/Projects/django/quiz /venv/lib/python3.13/site-packages/django/template/base.py", line 171, in render
    return self._render(context)
           ~~~~~~~~~~~~^^^^^^^^^
  File "/Users/petergangmei/Developer/Projects/django/quiz /venv/lib/python3.13/site-packages/django/template/base.py", line 163, in _render
    return self.nodelist.render(context)
           ~~~~~~~~~~~~~~~~~~~~^^^^^^^^^
  File "/Users/petergangmei/Developer/Projects/django/quiz /venv/lib/python3.13/site-packages/django/template/base.py", line 1008, in render
    return SafeString("".join([node.render_annotated(context) for node in self]))
                               ~~~~~~~~~~~~~~~~~~~~~^^^^^^^^^
  File "/Users/petergangmei/Developer/Projects/django/quiz /venv/lib/python3.13/site-packages/django/template/base.py", line 969, in render_annotated
    return self.render(context)
           ~~~~~~~~~~~^^^^^^^^^
  File "/Users/petergangmei/Developer/Projects/django/quiz /venv/lib/python3.13/site-packages/django/template/loader_tags.py", line 159, in render
    return compiled_parent._render(context)
           ~~~~~~~~~~~~~~~~~~~~~~~^^^^^^^^^
  File "/Users/petergangmei/Developer/Projects/django/quiz /venv/lib/python3.13/site-packages/django/template/base.py", line 163, in _render
    return self.nodelist.render(context)
           ~~~~~~~~~~~~~~~~~~~~^^^^^^^^^
  File "/Users/petergangmei/Developer/Projects/django/quiz /venv/lib/python3.13/site-packages/django/template/base.py", line 1008, in render
    return SafeString("".join([node.render_annotated(context) for node in self]))
                               ~~~~~~~~~~~~~~~~~~~~~^^^^^^^^^
  File "/Users/petergangmei/Developer/Projects/django/quiz /venv/lib/python3.13/site-packages/django/template/base.py", line 969, in render_annotated
    return self.render(context)
           ~~~~~~~~~~~^^^^^^^^^
  File "/Users/petergangmei/Developer/Projects/django/quiz /venv/lib/python3.13/site-packages/django/template/loader_tags.py", line 65, in render
    result = block.nodelist.render(context)
  File "/Users/petergangmei/Developer/Projects/django/quiz /venv/lib/python3.13/site-packages/django/template/base.py", line 1008, in render
    return SafeString("".join([node.render_annotated(context) for node in self]))
                               ~~~~~~~~~~~~~~~~~~~~~^^^^^^^^^
  File "/Users/petergangmei/Developer/Projects/django/quiz /venv/lib/python3.13/site-packages/django/template/base.py", line 969, in render_annotated
    return self.render(context)
           ~~~~~~~~~~~^^^^^^^^^
  File "/Users/petergangmei/Developer/Projects/django/quiz /venv/lib/python3.13/site-packages/django/template/defaulttags.py", line 480, in render
    url = reverse(view_name, args=args, kwargs=kwargs, current_app=current_app)
  File "/Users/petergangmei/Developer/Projects/django/quiz /venv/lib/python3.13/site-packages/django/urls/base.py", line 88, in reverse
    return resolver._reverse_with_prefix(view, prefix, *args, **kwargs)
           ~~~~~~~~~~~~~~~~~~~~~~~~~~~~~^^^^^^^^^^^^^^^^^^^^^^^^^^^^^^^
  File "/Users/petergangmei/Developer/Projects/django/quiz /venv/lib/python3.13/site-packages/django/urls/resolvers.py", line 831, in _reverse_with_prefix
    raise NoReverseMatch(msg)
django.urls.exceptions.NoReverseMatch: Reverse for 'assessment_question' not found. 'assessment_question' is not a valid view function or pattern name.
ERROR 2025-03-28 07:46:08,313 basehttp 27421 6180433920 "POST /quiz/1/start/ HTTP/1.1" 500 164256
ERROR 2025-03-28 11:03:20,170 log 52105 6191017984 Internal Server Error: /quiz/question/fc61e79b-9caa-4643-a54e-7e5e6cbca50b/
Traceback (most recent call last):
  File "/Users/petergangmei/Developer/Projects/django/quiz /venv/lib/python3.13/site-packages/django/core/handlers/exception.py", line 55, in inner
    response = get_response(request)
  File "/Users/petergangmei/Developer/Projects/django/quiz /venv/lib/python3.13/site-packages/django/core/handlers/base.py", line 197, in _get_response
    response = wrapped_callback(request, *callback_args, **callback_kwargs)
  File "/Users/petergangmei/Developer/Projects/django/quiz /app/utils.py", line 35, in wrapped_view
    return view_func(request, *args, **kwargs)
  File "/Users/petergangmei/Developer/Projects/django/quiz /app/views.py", line 59, in quiz_question
    user_quiz = get_object_or_404(UserQuiz, token=token)
  File "/Users/petergangmei/Developer/Projects/django/quiz /venv/lib/python3.13/site-packages/django/shortcuts.py", line 86, in get_object_or_404
    return queryset.get(*args, **kwargs)
           ~~~~~~~~~~~~^^^^^^^^^^^^^^^^^
  File "/Users/petergangmei/Developer/Projects/django/quiz /venv/lib/python3.13/site-packages/django/db/models/query.py", line 635, in get
    clone = self._chain() if self.query.combinator else self.filter(*args, **kwargs)
                                                        ~~~~~~~~~~~^^^^^^^^^^^^^^^^^
  File "/Users/petergangmei/Developer/Projects/django/quiz /venv/lib/python3.13/site-packages/django/db/models/query.py", line 1476, in filter
    return self._filter_or_exclude(False, args, kwargs)
           ~~~~~~~~~~~~~~~~~~~~~~~^^^^^^^^^^^^^^^^^^^^^
  File "/Users/petergangmei/Developer/Projects/django/quiz /venv/lib/python3.13/site-packages/django/db/models/query.py", line 1494, in _filter_or_exclude
    clone._filter_or_exclude_inplace(negate, args, kwargs)
    ~~~~~~~~~~~~~~~~~~~~~~~~~~~~~~~~^^^^^^^^^^^^^^^^^^^^^^
  File "/Users/petergangmei/Developer/Projects/django/quiz /venv/lib/python3.13/site-packages/django/db/models/query.py", line 1501, in _filter_or_exclude_inplace
    self._query.add_q(Q(*args, **kwargs))
    ~~~~~~~~~~~~~~~~~^^^^^^^^^^^^^^^^^^^^
  File "/Users/petergangmei/Developer/Projects/django/quiz /venv/lib/python3.13/site-packages/django/db/models/sql/query.py", line 1609, in add_q
    clause, _ = self._add_q(q_object, self.used_aliases)
                ~~~~~~~~~~~^^^^^^^^^^^^^^^^^^^^^^^^^^^^^
  File "/Users/petergangmei/Developer/Projects/django/quiz /venv/lib/python3.13/site-packages/django/db/models/sql/query.py", line 1641, in _add_q
    child_clause, needed_inner = self.build_filter(
                                 ~~~~~~~~~~~~~~~~~^
        child,
        ^^^^^^
    ...<7 lines>...
        update_join_types=update_join_types,
        ^^^^^^^^^^^^^^^^^^^^^^^^^^^^^^^^^^^^
    )
    ^
  File "/Users/petergangmei/Developer/Projects/django/quiz /venv/lib/python3.13/site-packages/django/db/models/sql/query.py", line 1491, in build_filter
    lookups, parts, reffed_expression = self.solve_lookup_type(arg, summarize)
                                        ~~~~~~~~~~~~~~~~~~~~~~^^^^^^^^^^^^^^^^
  File "/Users/petergangmei/Developer/Projects/django/quiz /venv/lib/python3.13/site-packages/django/db/models/sql/query.py", line 1303, in solve_lookup_type
    _, field, _, lookup_parts = self.names_to_path(lookup_splitted, self.get_meta())
                                ~~~~~~~~~~~~~~~~~~^^^^^^^^^^^^^^^^^^^^^^^^^^^^^^^^^^
  File "/Users/petergangmei/Developer/Projects/django/quiz /venv/lib/python3.13/site-packages/django/db/models/sql/query.py", line 1768, in names_to_path
    raise FieldError(
    ...<2 lines>...
    )
django.core.exceptions.FieldError: Cannot resolve keyword 'token' into field. Choices are: access_token, created_at, current_question, expires_at, id, ip_address, is_completed, quiz, quiz_id, responses, result_data, user_name
ERROR 2025-03-28 11:03:20,173 basehttp 52105 6191017984 "GET /quiz/question/fc61e79b-9caa-4643-a54e-7e5e6cbca50b/ HTTP/1.1" 500 124930
ERROR 2025-03-28 11:03:25,915 log 52105 6191017984 Internal Server Error: /quiz/question/fc61e79b-9caa-4643-a54e-7e5e6cbca50b/
Traceback (most recent call last):
  File "/Users/petergangmei/Developer/Projects/django/quiz /venv/lib/python3.13/site-packages/django/core/handlers/exception.py", line 55, in inner
    response = get_response(request)
  File "/Users/petergangmei/Developer/Projects/django/quiz /venv/lib/python3.13/site-packages/django/core/handlers/base.py", line 197, in _get_response
    response = wrapped_callback(request, *callback_args, **callback_kwargs)
  File "/Users/petergangmei/Developer/Projects/django/quiz /app/utils.py", line 35, in wrapped_view
    return view_func(request, *args, **kwargs)
  File "/Users/petergangmei/Developer/Projects/django/quiz /app/views.py", line 59, in quiz_question
    user_quiz = get_object_or_404(UserQuiz, token=token)
  File "/Users/petergangmei/Developer/Projects/django/quiz /venv/lib/python3.13/site-packages/django/shortcuts.py", line 86, in get_object_or_404
    return queryset.get(*args, **kwargs)
           ~~~~~~~~~~~~^^^^^^^^^^^^^^^^^
  File "/Users/petergangmei/Developer/Projects/django/quiz /venv/lib/python3.13/site-packages/django/db/models/query.py", line 635, in get
    clone = self._chain() if self.query.combinator else self.filter(*args, **kwargs)
                                                        ~~~~~~~~~~~^^^^^^^^^^^^^^^^^
  File "/Users/petergangmei/Developer/Projects/django/quiz /venv/lib/python3.13/site-packages/django/db/models/query.py", line 1476, in filter
    return self._filter_or_exclude(False, args, kwargs)
           ~~~~~~~~~~~~~~~~~~~~~~~^^^^^^^^^^^^^^^^^^^^^
  File "/Users/petergangmei/Developer/Projects/django/quiz /venv/lib/python3.13/site-packages/django/db/models/query.py", line 1494, in _filter_or_exclude
    clone._filter_or_exclude_inplace(negate, args, kwargs)
    ~~~~~~~~~~~~~~~~~~~~~~~~~~~~~~~~^^^^^^^^^^^^^^^^^^^^^^
  File "/Users/petergangmei/Developer/Projects/django/quiz /venv/lib/python3.13/site-packages/django/db/models/query.py", line 1501, in _filter_or_exclude_inplace
    self._query.add_q(Q(*args, **kwargs))
    ~~~~~~~~~~~~~~~~~^^^^^^^^^^^^^^^^^^^^
  File "/Users/petergangmei/Developer/Projects/django/quiz /venv/lib/python3.13/site-packages/django/db/models/sql/query.py", line 1609, in add_q
    clause, _ = self._add_q(q_object, self.used_aliases)
                ~~~~~~~~~~~^^^^^^^^^^^^^^^^^^^^^^^^^^^^^
  File "/Users/petergangmei/Developer/Projects/django/quiz /venv/lib/python3.13/site-packages/django/db/models/sql/query.py", line 1641, in _add_q
    child_clause, needed_inner = self.build_filter(
                                 ~~~~~~~~~~~~~~~~~^
        child,
        ^^^^^^
    ...<7 lines>...
        update_join_types=update_join_types,
        ^^^^^^^^^^^^^^^^^^^^^^^^^^^^^^^^^^^^
    )
    ^
  File "/Users/petergangmei/Developer/Projects/django/quiz /venv/lib/python3.13/site-packages/django/db/models/sql/query.py", line 1491, in build_filter
    lookups, parts, reffed_expression = self.solve_lookup_type(arg, summarize)
                                        ~~~~~~~~~~~~~~~~~~~~~~^^^^^^^^^^^^^^^^
  File "/Users/petergangmei/Developer/Projects/django/quiz /venv/lib/python3.13/site-packages/django/db/models/sql/query.py", line 1303, in solve_lookup_type
    _, field, _, lookup_parts = self.names_to_path(lookup_splitted, self.get_meta())
                                ~~~~~~~~~~~~~~~~~~^^^^^^^^^^^^^^^^^^^^^^^^^^^^^^^^^^
  File "/Users/petergangmei/Developer/Projects/django/quiz /venv/lib/python3.13/site-packages/django/db/models/sql/query.py", line 1768, in names_to_path
    raise FieldError(
    ...<2 lines>...
    )
django.core.exceptions.FieldError: Cannot resolve keyword 'token' into field. Choices are: access_token, created_at, current_question, expires_at, id, ip_address, is_completed, quiz, quiz_id, responses, result_data, user_name
ERROR 2025-03-28 11:03:25,918 basehttp 52105 6191017984 "GET /quiz/question/fc61e79b-9caa-4643-a54e-7e5e6cbca50b/ HTTP/1.1" 500 125198
ERROR 2025-03-28 11:03:33,225 log 52105 6191017984 Internal Server Error: /quiz/question/fc61e79b-9caa-4643-a54e-7e5e6cbca50b/
Traceback (most recent call last):
  File "/Users/petergangmei/Developer/Projects/django/quiz /venv/lib/python3.13/site-packages/django/core/handlers/exception.py", line 55, in inner
    response = get_response(request)
  File "/Users/petergangmei/Developer/Projects/django/quiz /venv/lib/python3.13/site-packages/django/core/handlers/base.py", line 197, in _get_response
    response = wrapped_callback(request, *callback_args, **callback_kwargs)
  File "/Users/petergangmei/Developer/Projects/django/quiz /app/utils.py", line 35, in wrapped_view
    return view_func(request, *args, **kwargs)
  File "/Users/petergangmei/Developer/Projects/django/quiz /app/views.py", line 59, in quiz_question
    user_quiz = get_object_or_404(UserQuiz, token=token)
  File "/Users/petergangmei/Developer/Projects/django/quiz /venv/lib/python3.13/site-packages/django/shortcuts.py", line 86, in get_object_or_404
    return queryset.get(*args, **kwargs)
           ~~~~~~~~~~~~^^^^^^^^^^^^^^^^^
  File "/Users/petergangmei/Developer/Projects/django/quiz /venv/lib/python3.13/site-packages/django/db/models/query.py", line 635, in get
    clone = self._chain() if self.query.combinator else self.filter(*args, **kwargs)
                                                        ~~~~~~~~~~~^^^^^^^^^^^^^^^^^
  File "/Users/petergangmei/Developer/Projects/django/quiz /venv/lib/python3.13/site-packages/django/db/models/query.py", line 1476, in filter
    return self._filter_or_exclude(False, args, kwargs)
           ~~~~~~~~~~~~~~~~~~~~~~~^^^^^^^^^^^^^^^^^^^^^
  File "/Users/petergangmei/Developer/Projects/django/quiz /venv/lib/python3.13/site-packages/django/db/models/query.py", line 1494, in _filter_or_exclude
    clone._filter_or_exclude_inplace(negate, args, kwargs)
    ~~~~~~~~~~~~~~~~~~~~~~~~~~~~~~~~^^^^^^^^^^^^^^^^^^^^^^
  File "/Users/petergangmei/Developer/Projects/django/quiz /venv/lib/python3.13/site-packages/django/db/models/query.py", line 1501, in _filter_or_exclude_inplace
    self._query.add_q(Q(*args, **kwargs))
    ~~~~~~~~~~~~~~~~~^^^^^^^^^^^^^^^^^^^^
  File "/Users/petergangmei/Developer/Projects/django/quiz /venv/lib/python3.13/site-packages/django/db/models/sql/query.py", line 1609, in add_q
    clause, _ = self._add_q(q_object, self.used_aliases)
                ~~~~~~~~~~~^^^^^^^^^^^^^^^^^^^^^^^^^^^^^
  File "/Users/petergangmei/Developer/Projects/django/quiz /venv/lib/python3.13/site-packages/django/db/models/sql/query.py", line 1641, in _add_q
    child_clause, needed_inner = self.build_filter(
                                 ~~~~~~~~~~~~~~~~~^
        child,
        ^^^^^^
    ...<7 lines>...
        update_join_types=update_join_types,
        ^^^^^^^^^^^^^^^^^^^^^^^^^^^^^^^^^^^^
    )
    ^
  File "/Users/petergangmei/Developer/Projects/django/quiz /venv/lib/python3.13/site-packages/django/db/models/sql/query.py", line 1491, in build_filter
    lookups, parts, reffed_expression = self.solve_lookup_type(arg, summarize)
                                        ~~~~~~~~~~~~~~~~~~~~~~^^^^^^^^^^^^^^^^
  File "/Users/petergangmei/Developer/Projects/django/quiz /venv/lib/python3.13/site-packages/django/db/models/sql/query.py", line 1303, in solve_lookup_type
    _, field, _, lookup_parts = self.names_to_path(lookup_splitted, self.get_meta())
                                ~~~~~~~~~~~~~~~~~~^^^^^^^^^^^^^^^^^^^^^^^^^^^^^^^^^^
  File "/Users/petergangmei/Developer/Projects/django/quiz /venv/lib/python3.13/site-packages/django/db/models/sql/query.py", line 1768, in names_to_path
    raise FieldError(
    ...<2 lines>...
    )
django.core.exceptions.FieldError: Cannot resolve keyword 'token' into field. Choices are: access_token, created_at, current_question, expires_at, id, ip_address, is_completed, quiz, quiz_id, responses, result_data, user_name
ERROR 2025-03-28 11:03:33,227 basehttp 52105 6191017984 "GET /quiz/question/fc61e79b-9caa-4643-a54e-7e5e6cbca50b/ HTTP/1.1" 500 124985
ERROR 2025-03-28 11:03:48,893 log 52105 6224097280 Internal Server Error: /quiz/1/start/
Traceback (most recent call last):
  File "/Users/petergangmei/Developer/Projects/django/quiz /venv/lib/python3.13/site-packages/django/core/handlers/exception.py", line 55, in inner
    response = get_response(request)
  File "/Users/petergangmei/Developer/Projects/django/quiz /venv/lib/python3.13/site-packages/django/core/handlers/base.py", line 197, in _get_response
    response = wrapped_callback(request, *callback_args, **callback_kwargs)
  File "/Users/petergangmei/Developer/Projects/django/quiz /app/utils.py", line 35, in wrapped_view
    return view_func(request, *args, **kwargs)
  File "/Users/petergangmei/Developer/Projects/django/quiz /app/views.py", line 44, in quiz_start
    'token': user_quiz.token
             ^^^^^^^^^^^^^^^
AttributeError: 'UserQuiz' object has no attribute 'token'
ERROR 2025-03-28 11:03:48,894 basehttp 52105 6224097280 "POST /quiz/1/start/ HTTP/1.1" 500 74515
ERROR 2025-03-28 11:05:59,744 log 53286 6158151680 Internal Server Error: /quiz/1/start/
Traceback (most recent call last):
  File "/Users/petergangmei/Developer/Projects/django/quiz /venv/lib/python3.13/site-packages/django/urls/base.py", line 71, in reverse
    extra, resolver = resolver.namespace_dict[ns]
                      ~~~~~~~~~~~~~~~~~~~~~~~^^^^
KeyError: 'app'

During handling of the above exception, another exception occurred:

Traceback (most recent call last):
  File "/Users/petergangmei/Developer/Projects/django/quiz /venv/lib/python3.13/site-packages/django/core/handlers/exception.py", line 55, in inner
    response = get_response(request)
  File "/Users/petergangmei/Developer/Projects/django/quiz /venv/lib/python3.13/site-packages/django/core/handlers/base.py", line 197, in _get_response
    response = wrapped_callback(request, *callback_args, **callback_kwargs)
  File "/Users/petergangmei/Developer/Projects/django/quiz /app/utils.py", line 35, in wrapped_view
    return view_func(request, *args, **kwargs)
  File "/Users/petergangmei/Developer/Projects/django/quiz /app/views.py", line 48, in quiz_start
    return redirect('app:quiz-question', token=user_quiz.token)
  File "/Users/petergangmei/Developer/Projects/django/quiz /venv/lib/python3.13/site-packages/django/shortcuts.py", line 49, in redirect
    return redirect_class(resolve_url(to, *args, **kwargs))
                          ~~~~~~~~~~~^^^^^^^^^^^^^^^^^^^^^
  File "/Users/petergangmei/Developer/Projects/django/quiz /venv/lib/python3.13/site-packages/django/shortcuts.py", line 180, in resolve_url
    return reverse(to, args=args, kwargs=kwargs)
  File "/Users/petergangmei/Developer/Projects/django/quiz /venv/lib/python3.13/site-packages/django/urls/base.py", line 82, in reverse
    raise NoReverseMatch("%s is not a registered namespace" % key)
django.urls.exceptions.NoReverseMatch: 'app' is not a registered namespace
ERROR 2025-03-28 11:05:59,746 basehttp 53286 6158151680 "POST /quiz/1/start/ HTTP/1.1" 500 96001
ERROR 2025-03-28 11:06:04,343 log 53286 6158151680 Internal Server Error: /quiz/1/start/
Traceback (most recent call last):
  File "/Users/petergangmei/Developer/Projects/django/quiz /venv/lib/python3.13/site-packages/django/urls/base.py", line 71, in reverse
    extra, resolver = resolver.namespace_dict[ns]
                      ~~~~~~~~~~~~~~~~~~~~~~~^^^^
KeyError: 'app'

During handling of the above exception, another exception occurred:

Traceback (most recent call last):
  File "/Users/petergangmei/Developer/Projects/django/quiz /venv/lib/python3.13/site-packages/django/core/handlers/exception.py", line 55, in inner
    response = get_response(request)
  File "/Users/petergangmei/Developer/Projects/django/quiz /venv/lib/python3.13/site-packages/django/core/handlers/base.py", line 197, in _get_response
    response = wrapped_callback(request, *callback_args, **callback_kwargs)
  File "/Users/petergangmei/Developer/Projects/django/quiz /app/utils.py", line 35, in wrapped_view
    return view_func(request, *args, **kwargs)
  File "/Users/petergangmei/Developer/Projects/django/quiz /app/views.py", line 48, in quiz_start
    return redirect('app:quiz-question', token=user_quiz.token)
  File "/Users/petergangmei/Developer/Projects/django/quiz /venv/lib/python3.13/site-packages/django/shortcuts.py", line 49, in redirect
    return redirect_class(resolve_url(to, *args, **kwargs))
                          ~~~~~~~~~~~^^^^^^^^^^^^^^^^^^^^^
  File "/Users/petergangmei/Developer/Projects/django/quiz /venv/lib/python3.13/site-packages/django/shortcuts.py", line 180, in resolve_url
    return reverse(to, args=args, kwargs=kwargs)
  File "/Users/petergangmei/Developer/Projects/django/quiz /venv/lib/python3.13/site-packages/django/urls/base.py", line 82, in reverse
    raise NoReverseMatch("%s is not a registered namespace" % key)
django.urls.exceptions.NoReverseMatch: 'app' is not a registered namespace
ERROR 2025-03-28 11:06:04,345 basehttp 53286 6158151680 "POST /quiz/1/start/ HTTP/1.1" 500 96001
